Workbook
Name Slicer_Customer_Category: #N/A
Name Slicer_Product_Category1: #N/A
Name Slicer_Region1: #N/A

Sheet Dashboard

Sheet Wireframe

Sheet Pivot Table
A1: KPI CARDS | D1: METRICS | S1: SLICERS
A3: Total Net Sales | D3: Top Customers | J3: Customer Segment | O3: Row Labels | P3: Sum of Net Sales
A4: Sum of Net Sales | D4: Row Labels | E4: Sum of Net Sales | J4: Row Labels | K4: Sum of Net Sales | O4: Furnishings | P4: 89239.533
A5: 1792865.2 | B5: =GETPIVOTDATA("[Measures].[Sum of Net Sales]",$A$4) -> 1792865.2 | D5: Andrew Levine | E5: 15117.309 | J5: Consumer | K5: 0.20597972 | O5: Copiers | P5: 90593.372
D6: Lee Xu | E6: 17385.621 | J6: Small Business | K6: 0.20690483 | O6: Computer Peripherals | P6: 91124.595
D7: Tammy Raynor | E7: 17404.649 | J7: Home Office | K7: 0.24216094 | O7: Bookcases | P7: 96686.382
A8: Average Shipping Duration | D8: Erin Ballard | E8: 17876.052 | J8: Corporate | K8: 0.34495452 | O8: Storage | P8: 161490.43
A9: Average of Shipping Duration | D9: Neal Wolfe | E9: 17962.603 | J9: Grand Total | K9: 1 | O9: Binders | P9: 165163.96
A10: 1.9405738 | B10: =GETPIVOTDATA("[Measures].[Average of Shipping Duration]",$A$9) -> 1.9405738 | D10: Rosemary O'Brien | E10: 25446.897 | O10: Tables | P10: 182409.62
D11: Toni Swanson | E11: 25899.396 | O11: Telephones | P11: 214898.58
D12: Yvonne Mann | E12: 26042.985 | J12: Weekday Trend | O12: Chairs | P12: 234239.99
A13: Total Unique Order | D13: Nina Horne Kelly | E13: 41244.551 | J13: Row Labels | K13: Sum of Net Sales | O13: Office Machines | P13: 291698.21
A14: Distinct Count of Order ID | D14: Kristine Connolly | E14: 50082.845 | J14: Sunday | K14: 201509.31 | O14: Grand Total | P14: 1617544.7
A15: 1365 | B15: =GETPIVOTDATA("[Measures].[Distinct Count of Order ID]",$A$14) -> 1365 | D15: Grand Total | E15: 254462.91 | J15: Monday | K15: 237292.75
J16: Tuesday | K16: 216651.63
J17: Wednesday | K17: 208906.92
A18: Total Unique Customer | D18: Order Priority | J18: Thursday | K18: 227154.87
A19: Distinct Count of Customer ID | D19: Row Labels | E19: Sum of Net Sales | J19: Friday | K19: 281920.82
A20: 1130 | B20: =GETPIVOTDATA("[Measures].[Distinct Count of Customer ID]",$A$19) -> 1130 | D20: Critical | E20: 408217.27 | J20: Saturday | K20: 419428.92
D21: High | E21: 291819.29 | J21: Grand Total | K21: 1792865.2
D22: Low | E22: 356144.84
A23: Average Discount | D23: Medium | E23: 345591.01
A24: Average of Discount | D24: Not Specified | E24: 391092.82 | J24: ship mode
A25: 0.063242828 | B25: =GETPIVOTDATA("[Measures].[Average of Discount]",$A$24)/100*100 -> 0.063242828 | D25: Grand Total | E25: 1792865.2 | J25: Row Labels | K25: Sum of Net Sales
J26: Standard | K26: 1167960.5 | L26: =GETPIVOTDATA("[Measures].[Sum of Net Sales]",$J$25,"[Table1].[Ship Mode]","[Table1].[Ship Mode].&[Standard]") -> 1167960.5 | M26: =$L26/GETPIVOTDATA("[Measures].[Sum of Net Sales]",$J$25) -> 0.65144913
D27: Orders by Month | J27: Express | K27: 624904.74 | L27: =GETPIVOTDATA("[Measures].[Sum of Net Sales]",$J$25,"[Table1].[Ship Mode]","[Table1].[Ship Mode].&[Express]") -> 624904.74 | M27: =$L27/GETPIVOTDATA("[Measures].[Sum of Net Sales]",$J$25) -> 0.34855087
D28: Row Labels | E28: Sum of Net Sales | J28: Grand Total | K28: 1792865.2
D29: January | E29: 256180.52 | M29: =SUM(M26:M27) -> 1
D30: February | E30: 311793.14
D31: March | E31: 254940.08 | J31: Product
D32: April | E32: 356920.81 | J32: Row Labels | K32: Sum of Net Sales
D33: May | E33: 288944.42 | J33: Rubber Bands | K33: 1658.928
D34: June | E34: 324086.25 | J34: Labels | K34: 4687.509
D35: Grand Total | E35: 1792865.2 | J35: Scissors | K35: 6099.51
J36: Envelopes | K36: 9810.0745
J37: Pens | K37: 24954.552
J38: Paper | K38: 52472.218
D39: Customer Category | J39: Appliances | K39: 75637.745
D40: Row Labels | E40: Sum of Net Sales | J40: Furnishings | K40: 89239.533
D41: New Customer | E41: 445041.43 | F41: =GETPIVOTDATA("[Measures].[Sum of Net Sales 2]",$D$40,"[Range].[Customer Category]","[Range].[Customer Category].&[New Customer]") -> 445041.43 | G41: =F41/GETPIVOTDATA("[Measures].[Sum of Net Sales 2]",$D$40) -> 0.24822916 | H41: =MAX(E41:E42) -> 1347823.8 | J41: Copiers | K41: 90593.372
...

Sheet Calculated Metrics
A1: Row ID | B1: Order Priority | C1: Order ID | D1: Unit Price | E1: Discount | F1: Quantity ordered | G1: Net Sales | H1: Customer ID | I1: Customer Name | J1: Customer Category | K1: Customer Segment | L1: Ship Mode | M1: Order Date | N1: Ship Date | O1: Shipping Duration | P1: Order Month | Q1: Order Day | R1: Product Name | S1: Product Category | T1: Product Sub-Category | U1: Product Container | V1: Country | W1: Region | X1: State or Province | Y1: City | Z1: Postal Code
A2: 20847 | B2: High | C2: 88522 | D2: 2.84 | E2: 0.05 | F2: 4 | G2: ='Calculated Metrics'!$D2*'Calculated Metrics'!$F2*(1-'Calculated Metrics'!$E2) -> 10.792 | H2: 3 | I2: Bonnie Potter | J2: =IF(COUNTIF(I:I,I2)>1,"Returning Customer","New Customer") -> New Customer | K2: Corporate | L2: Express | M2: 42011 | N2: 42012 | O2: ='Calculated Metrics'!$N2-'Calculated Metrics'!$M2 -> 1 | P2: =TEXT('Calculated Metrics'!$M2,"mmmm") -> January | Q2: =TEXT('Calculated Metrics'!$M2,"dddd") -> Wednesday | R2: =_xlfn.XLOOKUP('Calculated Metrics'!$T2,'Product Lookup'!A:A,'Product Lookup'!B:B, ,0) -> Pens | S2: Office Supplies | T2: Pens & Art Supplies | U2: Wrap Bag | V2: United States | W2: West | X2: Washington | Y2: Anacortes | Z2: 98221
A3: 20228 | B3: Not Specified | C3: 90193 | D3: 500.98 | E3: 0.1 | F3: 12 | G3: ='Calculated Metrics'!$D3*'Calculated Metrics'!$F3*(1-'Calculated Metrics'!$E3) -> 5410.584 | H3: 5 | I3: Ronnie Proctor | J3: =IF(COUNTIF(I:I,I3)>1,"Returning Customer","New Customer") -> New Customer | K3: Home Office | L3: Standard | M3: 42168 | N3: 42170 | O3: ='Calculated Metrics'!$N3-'Calculated Metrics'!$M3 -> 2 | P3: =TEXT('Calculated Metrics'!$M3,"mmmm") -> June | Q3: =TEXT('Calculated Metrics'!$M3,"dddd") -> Saturday | R3: =_xlfn.XLOOKUP('Calculated Metrics'!$T3,'Product Lookup'!A:A,'Product Lookup'!B:B, ,0) -> Chairs | S3: Furniture | T3: Chairs & Chairmats | U3: Jumbo Drum | V3: United States | W3: West | X3: California | Y3: San Gabriel | Z3: 91776
A4: 21776 | B4: Critical | C4: 90192 | D4: 9.48 | E4: 0.05 | F4: 22 | G4: ='Calculated Metrics'!$D4*'Calculated Metrics'!$F4*(1-'Calculated Metrics'!$E4) -> 198.132 | H4: 11 | I4: Marcus Dunlap | J4: =IF(COUNTIF(I:I,I4)>1,"Returning Customer","New Customer") -> New Customer | K4: Home Office | L4: Standard | M4: 42050 | N4: 42052 | O4: ='Calculated Metrics'!$N4-'Calculated Metrics'!$M4 -> 2 | P4: =TEXT('Calculated Metrics'!$M4,"mmmm") -> February | Q4: =TEXT('Calculated Metrics'!$M4,"dddd") -> Sunday | R4: =_xlfn.XLOOKUP('Calculated Metrics'!$T4,'Product Lookup'!A:A,'Product Lookup'!B:B, ,0) -> Furnishings | S4: Furniture | T4: Office Furnishings | U4: Small Pack | V4: United States | W4: East | X4: New Jersey | Y4: Roselle | Z4: 7203
A5: 24844 | B5: Medium | C5: 86838 | D5: 78.69 | E5: 0.05 | F5: 16 | G5: ='Calculated Metrics'!$D5*'Calculated Metrics'!$F5*(1-'Calculated Metrics'!$E5) -> 1196.088 | H5: 14 | I5: Gwendolyn F Tyson | J5: =IF(COUNTIF(I:I,I5)>1,"Returning Customer","New Customer") -> Returning Customer | K5: Small Business | L5: Standard | M5: 42136 | N5: 42138 | O5: ='Calculated Metrics'!$N5-'Calculated Metrics'!$M5 -> 2 | P5: =TEXT('Calculated Metrics'!$M5,"mmmm") -> May | Q5: =TEXT('Calculated Metrics'!$M5,"dddd") -> Tuesday | R5: =_xlfn.XLOOKUP('Calculated Metrics'!$T5,'Product Lookup'!A:A,'Product Lookup'!B:B, ,0) -> Furnishings | S5: Furniture | T5: Office Furnishings | U5: Small Box | V5: United States | W5: Central | X5: Minnesota | Y5: Prior Lake | Z5: 55372
A6: 24846 | B6: Medium | C6: 86838 | D6: 3.28 | E6: 0.05 | F6: 7 | G6: ='Calculated Metrics'!$D6*'Calculated Metrics'!$F6*(1-'Calculated Metrics'!$E6) -> 21.812 | H6: 14 | I6: Gwendolyn F Tyson | J6: =IF(COUNTIF(I:I,I6)>1,"Returning Customer","New Customer") -> Returning Customer | K6: Small Business | L6: Standard | M6: 42136 | N6: 42137 | O6: ='Calculated Metrics'!$N6-'Calculated Metrics'!$M6 -> 1 | P6: =TEXT('Calculated Metrics'!$M6,"mmmm") -> May | Q6: =TEXT('Calculated Metrics'!$M6,"dddd") -> Tuesday | R6: =_xlfn.XLOOKUP('Calculated Metrics'!$T6,'Product Lookup'!A:A,'Product Lookup'!B:B, ,0) -> Pens | S6: Office Supplies | T6: Pens & Art Supplies | U6: Wrap Bag | V6: United States | W6: Central | X6: Minnesota | Y6: Prior Lake | Z6: 55372
A7: 24847 | B7: Medium | C7: 86838 | D7: 3.28 | E7: 0.05 | F7: 4 | G7: ='Calculated Metrics'!$D7*'Calculated Metrics'!$F7*(1-'Calculated Metrics'!$E7) -> 12.464 | H7: 14 | I7: Gwendolyn F Tyson | J7: =IF(COUNTIF(I:I,I7)>1,"Returning Customer","New Customer") -> Returning Customer | K7: Small Business | L7: Standard | M7: 42136 | N7: 42137 | O7: ='Calculated Metrics'!$N7-'Calculated Metrics'!$M7 -> 1 | P7: =TEXT('Calculated Metrics'!$M7,"mmmm") -> May | Q7: =TEXT('Calculated Metrics'!$M7,"dddd") -> Tuesday | R7: =_xlfn.XLOOKUP('Calculated Metrics'!$T7,'Product Lookup'!A:A,'Product Lookup'!B:B, ,0) -> Pens | S7: Office Supplies | T7: Pens & Art Supplies | U7: Wrap Bag | V7: United States | W7: Central | X7: Minnesota | Y7: Prior Lake | Z7: 55372
A8: 24848 | B8: Medium | C8: 86838 | D8: 3.58 | E8: 0.05 | F8: 4 | G8: ='Calculated Metrics'!$D8*'Calculated Metrics'!$F8*(1-'Calculated Metrics'!$E8) -> 13.604 | H8: 14 | I8: Gwendolyn F Tyson | J8: =IF(COUNTIF(I:I,I8)>1,"Returning Customer","New Customer") -> Returning Customer | K8: Small Business | L8: Standard | M8: 42136 | N8: 42137 | O8: ='Calculated Metrics'!$N8-'Calculated Metrics'!$M8 -> 1 | P8: =TEXT('Calculated Metrics'!$M8,"mmmm") -> May | Q8: =TEXT('Calculated Metrics'!$M8,"dddd") -> Tuesday | R8: =_xlfn.XLOOKUP('Calculated Metrics'!$T8,'Product Lookup'!A:A,'Product Lookup'!B:B, ,0) -> Rubber Bands | S8: Office Supplies | T8: Rubber Bands | U8: Wrap Bag | V8: United States | W8: East | X8: Minnesota | Y8: Prior Lake | Z8: 55372
A9: 18181 | B9: Critical | C9: 86837 | D9: 4.42 | E9: 0.05 | F9: 7 | G9: ='Calculated Metrics'!$D9*'Calculated Metrics'!$F9*(1-'Calculated Metrics'!$E9) -> 29.393 | H9: 15 | I9: Timothy Reese | J9: =IF(COUNTIF(I:I,I9)>1,"Returning Customer","New Customer") -> Returning Customer | K9: Small Business | L9: Standard | M9: 42102 | N9: 42103 | O9: ='Calculated Metrics'!$N9-'Calculated Metrics'!$M9 -> 1 | P9: =TEXT('Calculated Metrics'!$M9,"mmmm") -> April | Q9: =TEXT('Calculated Metrics'!$M9,"dddd") -> Wednesday | R9: =_xlfn.XLOOKUP('Calculated Metrics'!$T9,'Product Lookup'!A:A,'Product Lookup'!B:B, ,0) -> Envelopes | S9: Office Supplies | T9: Envelopes | U9: Small Box | V9: United States | W9: East | X9: New York | Y9: Smithtown | Z9: 11787
A10: 20925 | B10: Medium | C10: 86839 | D10: 35.94 | E10: 0.05 | F10: 10 | G10: ='Calculated Metrics'!$D10*'Calculated Metrics'!$F10*(1-'Calculated Metrics'!$E10) -> 341.43 | H10: 15 | I10: Timothy Reese | J10: =IF(COUNTIF(I:I,I10)>1,"Returning Customer","New Customer") -> Returning Customer | K10: Small Business | L10: Standard | M10: 42152 | N10: 42152 | O10: ='Calculated Metrics'!$N10-'Calculated Metrics'!$M10 -> 0 | P10: =TEXT('Calculated Metrics'!$M10,"mmmm") -> May | Q10: =TEXT('Calculated Metrics'!$M10,"dddd") -> Thursday | R10: =_xlfn.XLOOKUP('Calculated Metrics'!$T10,'Product Lookup'!A:A,'Product Lookup'!B:B, ,0) -> Envelopes | S10: Office Supplies | T10: Envelopes | U10: Small Box | V10: United States | W10: East | X10: New York | Y10: Smithtown | Z10: 11787
A11: 26267 | B11: High | C11: 86836 | D11: 2.98 | E11: 0.05 | F11: 6 | G11: ='Calculated Metrics'!$D11*'Calculated Metrics'!$F11*(1-'Calculated Metrics'!$E11) -> 16.986 | H11: 16 | I11: Sarah Ramsey | J11: =IF(COUNTIF(I:I,I11)>1,"Returning Customer","New Customer") -> Returning Customer | K11: Small Business | L11: Standard | M11: 42047 | N11: 42050 | O11: ='Calculated Metrics'!$N11-'Calculated Metrics'!$M11 -> 3 | P11: =TEXT('Calculated Metrics'!$M11,"mmmm") -> February | Q11: =TEXT('Calculated Metrics'!$M11,"dddd") -> Thursday | R11: =_xlfn.XLOOKUP('Calculated Metrics'!$T11,'Product Lookup'!A:A,'Product Lookup'!B:B, ,0) -> Rubber Bands | S11: Office Supplies | T11: Rubber Bands | U11: Wrap Bag | V11: United States | W11: East | X11: New York | Y11: Syracuse | Z11: 13210
A12: 26268 | B12: High | C12: 86836 | D12: 115.99 | E12: 0.1 | F12: 10 | G12: ='Calculated Metrics'!$D12*'Calculated Metrics'!$F12*(1-'Calculated Metrics'!$E12) -> 1043.91 | H12: 16 | I12: Sarah Ramsey | J12: =IF(COUNTIF(I:I,I12)>1,"Returning Customer","New Customer") -> Returning Customer | K12: Small Business | L12: Standard | M12: 42047 | N12: 42049 | O12: ='Calculated Metrics'!$N12-'Calculated Metrics'!$M12 -> 2 | P12: =TEXT('Calculated Metrics'!$M12,"mmmm") -> February | Q12: =TEXT('Calculated Metrics'!$M12,"dddd") -> Thursday | R12: =_xlfn.XLOOKUP('Calculated Metrics'!$T12,'Product Lookup'!A:A,'Product Lookup'!B:B, ,0) -> Telephones | S12: Technology | T12: Telephones And Communication | U12: Small Box | V12: United States | W12: West | X12: New York | Y12: Syracuse | Z12: 13210
A13: 23890 | B13: High | C13: 90031 | D13: 26.48 | E13: 0.05 | F13: 17 | G13: ='Calculated Metrics'!$D13*'Calculated Metrics'!$F13*(1-'Calculated Metrics'!$E13) -> 427.652 | H13: 18 | I13: Laurie Hanna | J13: =IF(COUNTIF(I:I,I13)>1,"Returning Customer","New Customer") -> New Customer | K13: Small Business | L13: Standard | M13: 42139 | N13: 42140 | O13: ='Calculated Metrics'!$N13-'Calculated Metrics'!$M13 -> 1 | P13: =TEXT('Calculated Metrics'!$M13,"mmmm") -> May | Q13: =TEXT('Calculated Metrics'!$M13,"dddd") -> Friday | R13: =_xlfn.XLOOKUP('Calculated Metrics'!$T13,'Product Lookup'!A:A,'Product Lookup'!B:B, ,0) -> Furnishings | S13: Furniture | T13: Office Furnishings | U13: Small Box | V13: United States | W13: West | X13: Montana | Y13: Helena | Z13: 59601
... A1953: 25914 | B1953: High | C1953: 87530 | D1953: 105.98 | E1953: 0.1 | F1953: 5 | G1953: ='Calculated Metrics'!$D1953*'Calculated Metrics'!$F1953*(1-'Calculated Metrics'!$E1953) -> 476.91 | H1953: 3403 | I1953: Tammy Buckley | J1953: =IF(COUNTIF(I:I,I1953)>1,"Returning Customer","New Customer") -> New Customer | K1953: Consumer | L1953: Express | M1953: 42043 | N1953: 42046 | O1953: ='Calculated Metrics'!$N1953-'Calculated Metrics'!$M1953 -> 3 | P1953: =TEXT('Calculated Metrics'!$M1953,"mmmm") -> February | Q1953: =TEXT('Calculated Metrics'!$M1953,"dddd") -> Sunday | R1953: =_xlfn.XLOOKUP('Calculated Metrics'!$T1953,'Product Lookup'!A:A,'Product Lookup'!B:B, ,0) -> Furnishings | S1953: Furniture | T1953: Office Furnishings | U1953: Medium Box | V1953: United States | W1953: West | X1953: Wyoming | Y1953: Cheyenne | Z1953: 82001
G1954: =SUM('Calculated Metrics'!$G$2:$G$1953) -> 1792865.2

Sheet Product Lookup
A1: Product Sub-Category | B1: Product Name
A2: Pens & Art Supplies | B2: Pens
A3: Chairs & Chairmats | B3: Chairs
A4: Office Furnishings | B4: Furnishings
A5: Rubber Bands | B5: Rubber Bands
A6: Envelopes | B6: Envelopes
A7: Telephones And Communication | B7: Telephones
A8: Office Machines | B8: Office Machines
A9: Paper | B9: Paper
A10: Binders And Binder Accessories | B10: Binders
A11: Labels | B11: Labels
A12: Storage & Organization | B12: Storage
... A18: Copiers And Fax | B18: Copiers

Sheet Customer Lookup
A1: Customer ID | B1: Customer Name
A2: 3 | B2: Bonnie Potter
A3: 5 | B3: Ronnie Proctor
A4: 11 | B4: Marcus Dunlap
A5: 14 | B5: Gwendolyn F Tyson
A6: 14 | B6: Gwendolyn F Tyson
A7: 14 | B7: Gwendolyn F Tyson
A8: 14 | B8: Gwendolyn F Tyson
A9: 15 | B9: Timothy Reese
A10: 15 | B10: Timothy Reese
A11: 16 | B11: Sarah Ramsey
A12: 16 | B12: Sarah Ramsey
A13: 18 | B13: Laurie Hanna
... A1953: 3403 | B1953: Tammy Buckley

Sheet Raw Data
A1: Row ID | B1: Order Priority | C1: Unit Price | D1: Discount | E1: Customer ID | G1: Customer Name | H1: Ship Mode | I1: Customer Segment | J1: Product Category | K1: Product Sub-Category | L1: Product Container | M1: Product Name | N1: Country | O1: Region | P1: State or Province | Q1: City | S1: Postal Code | T1: Order Date | U1: Ship Date | V1: Quantity ordered | W1: Order ID
A2: 20847 | B2: high | C2: 2.84 | D2: 0.05 | E2: 3 | H2: express | I2: Corporateee | J2: Office Supplies | K2: Pens & Art Supplies | L2: Wrap Bag | N2: United States | O2: west | P2: Washington | Q2: Anacortes | S2: 98221 | T2: 42011 | U2: 42012 | V2: 4 | W2: 88522
A3: 20847 | B3: high | C3: 2.84 | D3: 0.05 | E3: 3 | H3: express | I3: Corporateee | J3: Office Supplies | K3: Pens & Art Supplies | L3: Wrap Bag | N3: United States | O3: west | P3: Washington | Q3: Anacortes | S3: 98221 | T3: 42011 | U3: 42012 | V3: 4 | W3: 88522
A4: 20228 | B4: Not Specified | C4: 500.98 | D4: 0.1 | E4: 5 | H4: Standard | I4: Home Officess | J4: Furniture | K4: Chairs & Chairmats | L4: Jumbo Drum | N4: United States | O4: west | P4: California | Q4: San Gabriel | S4: 91776 | T4: 42168 | U4: 42170 | V4: 12 | W4: 90193
A5: 21776 | B5: Critical | C5: 9.48 | D5: 0.05 | E5: 11 | H5: Standard | I5: Home Office | J5: Furniture | K5: office furnishings | L5: Small Pack | N5: United States | O5: east | P5: New Jersey | Q5: Roselle | S5: 7203 | T5: 42050 | U5: 42052 | V5: 22 | W5: 90192
A6: 24844 | B6: Medium | C6: 78.69 | D6: 0.05 | E6: 14 | H6: Standard | I6: Small Business | J6: Furniture | K6: Office Furnishings | L6: Small Box | N6: United States | O6: central | P6: Minnesota | Q6: Prior Lake | S6: 55372 | T6: 42136 | U6: 42138 | V6: 16 | W6: 86838
A7: 24846 | B7: Medium | C7: 3.28 | D7: 0.05 | E7: 14 | H7: Standard | I7: Small Business | J7: Office Supplies | K7: Pens & Art Supplies | L7: Wrap Bag | N7: United States | O7: central | P7: Minnesota | Q7: Prior Lake | S7: 55372 | T7: 42136 | U7: 42137 | V7: 7 | W7: 86838
A8: 24846 | B8: Medium | C8: 3.28 | D8: 0.05 | E8: 14 | H8: Standard | I8: Small Business | J8: Office Supplies | K8: Pens & Art Supplies | L8: Wrap Bag | N8: United States | O8: central | P8: Minnesota | Q8: Prior Lake | S8: 55372 | T8: 42136 | U8: 42137 | V8: 7 | W8: 86838
A9: 24846 | B9: Medium | C9: 3.28 | D9: 0.05 | E9: 14 | H9: Standard | I9: Small Business | J9: Office Supplies | K9: Pens & Art Supplies | L9: Wrap Bag | N9: United States | O9: central | P9: Minnesota | Q9: Prior Lake | S9: 55372 | T9: 42136 | U9: 42137 | V9: 7 | W9: 86838
A10: 24846 | B10: Medium | C10: 3.28 | D10: 0.05 | E10: 14 | H10: Standard | I10: Small Business | J10: Office Supplies | K10: Pens & Art Supplies | L10: Wrap Bag | N10: United States | O10: central | P10: Minnesota | Q10: Prior Lake | S10: 55372 | T10: 42136 | U10: 42137 | V10: 7 | W10: 86838
A11: 24846 | B11: Medium | C11: 3.28 | D11: 0.05 | E11: 14 | H11: Standard | I11: Small Business | J11: Office Supplies | K11: Pens & Art Supplies | L11: Wrap Bag | N11: United States | O11: central | P11: Minnesota | Q11: Prior Lake | S11: 55372 | T11: 42136 | U11: 42137 | V11: 7 | W11: 86838
A12: 24847 | B12: Medium | C12: 3.28 | D12: 0.05 | E12: 14 | H12: Standard | I12: Small Business | J12: Office Supplies | K12: Pens & Art Supplies | L12: Wrap Bag | N12: United States | O12: central | P12: Minnesota | Q12: Prior Lake | S12: 55372 | T12: 42136 | U12: 42137 | V12: 4 | W12: 86838
A13: 24848 | B13: Medium | C13: 3.58 | D13: 0.05 | E13: 14 | H13: Standard | I13: Small Business | J13: Office Supplies | K13: Rubber Bands | L13: Wrap Bag | N13: United States | O13: east | P13: Minnesota | Q13: Prior Lake | S13: 55372 | T13: 42136 | U13: 42137 | V13: 4 | W13: 86838
... A1961: 25914 | B1961: High | C1961: 105.98 | D1961: 0.1 | E1961: 3403 | H1961: Express | I1961: Consumer | J1961: Furniture | K1961: Office Furnishings | L1961: Medium Box | N1961: United States | O1961: West | P1961: Wyoming | Q1961: Cheyenne | S1961: 82001 | T1961: 42043 | U1961: 42046 | V1961: 5 | W1961: 87530
